Workbook

Sheet LEIA-ME
A1: Simples GRC — Planilha do portal (mesma sequência do roadmap)
A2: Todos os dados vêm do portal HTML. Premissas próprias estão sinalizadas em RISCO_PARAMETROS (azul sobre amarelo). Gerada em 03/10/2026.
A4: Aba | B4: Etapa do portal | C4: Conteúdo | D4: Nº de itens
A5: TOTAIS | B5: Resumo | C5: Totais e checagens de todo o roadmap
A6: 0_PERFIL_108 | B6: Etapa 0 | C6: Perfil: quem é a empresa | D6: =COUNTA(0_PERFIL_108!A5:A112) -> 108
A7: I_ESSENCIAIS_10 | B7: Etapa I | C7: Pacto Essencial: 10 medidas mínimas | D7: =COUNTA(I_ESSENCIAIS_10!A5:A14) -> 10
A8: II_PACTO_80_ITENS | B8: Etapa II | C8: Pacto Completo: catálogo de 80 itens (11 + 69) | D8: =COUNTA(II_PACTO_80_ITENS!A5:A84) -> 80
A9: II_PACTO_COMPL_69 | B9: Etapa II | C9: Complemento do Pacto: 69 itens | D9: =COUNTA(II_PACTO_COMPL_69!A5:A73) -> 69
A10: II_PACTO_QPE_76 | B10: Etapa II | C10: QPE correlatas ao Pacto | D10: =COUNTA(II_PACTO_QPE_76!A5:A80) -> 76
A11: III_PROETICA_137 | B11: Etapa III | C11: Complemento do Pró-Ética | D11: =COUNTA(III_PROETICA_137!A5:A141) -> 137
A12: III_AREAS_CGU | B12: Etapa III | C12: 10 áreas, tetos e mínimo de 45% | D12: =COUNTA(III_AREAS_CGU!B5:B14) -> 10
A13: IV_ISO_COMPL_27 | B13: Etapa IV | C13: Complemento ISO 37301/37001 | D13: =COUNTA(IV_ISO_COMPL_27!A5:A31) -> 27
A14: IV_ISO_REAPROV_24 | B14: Etapa IV | C14: ISO reaproveitável | D14: =COUNTA(IV_ISO_REAPROV_24!A5:A28) -> 24
A15: AG_PERFIL_108 | B15: Agentes | C15: Agentes de verificação do Perfil | D15: =COUNTA(AG_PERFIL_108!A5:A112) -> 108
A16: AG_CONFORMIDADE_223 | B16: Agentes | C16: Agentes de verificação da Conformidade | D16: =COUNTA(AG_CONFORMIDADE_223!A5:A227) -> 223
A17: AG_ISO_51 | B17: Agentes | C17: Agentes de verificação ISO | D17: =COUNTA(AG_ISO_51!A5:A55) -> 51
A18: LIC_CHECKLIST_14133 | B18: Licitações | C18: Checagem com a Lei 14.133/2021 | D18: =COUNTA(LIC_CHECKLIST_14133!A5:A16) -> 12
A19: LIC_PERGUNTAS | B19: Licitações | C19: Perguntas relevantes para licitações | D19: =COUNTA(LIC_PERGUNTAS!A5:A23) -> 19
A20: CONF_MATRIZ_108 | B20: Conflitos | C20: Matriz de conflitos Perfil × Conformidade | D20: =COUNTA(CONF_MATRIZ_108!A5:A112) -> 108
A21: CONF_REGRAS_42 | B21: Conflitos | C21: Regras de conflito | D21: =COUNTA(CONF_REGRAS_42!A5:A46) -> 42
A22: CONF_DEPENDENCIAS_23 | B22: Conflitos | C22: Regras de dependência | D22: =COUNTA(CONF_DEPENDENCIAS_23!A5:A27) -> 23
A23: RISCO_PARAMETROS | B23: Riscos | C23: Premissas editáveis (meta, apetite, capacidade, datas)
A24: RISCO_MATRIZ_17 | B24: Riscos | C24: Matriz de risco P×I (editável) | D24: =COUNTA(RISCO_MATRIZ_17!A5:A21) -> 17
A25: RISCO_ESTRESSE | B25: Riscos | C25: 5 cenários de estresse | D25: =COUNTA(RISCO_ESTRESSE!A5:A9) -> 5
A26: RISCO_SIMULADOR | B26: Riscos | C26: Simulador de probabilidade × impacto | D26: =COUNTA(RISCO_SIMULADOR!A6:A22) -> 17
A27: RISCO_MAPA_CALOR | B27: Riscos | C27: Mapa de calor base × simulado
A28: SIM_PROETICA | B28: Riscos | C28: Simulador da pontuação Pró-Ética (70 pts e 45%)
A29: PMO_BIBLIOTECA_25 | B29: PMO | C29: Biblioteca de ações | D29: =COUNTA(PMO_BIBLIOTECA_25!A5:A29) -> 25
A30: PMO_PLANO | B30: PMO | C30: Quadro do PMO | D30: =COUNTIF(PMO_PLANO!D10:D44,"?*") -> 25
A31: PMO_COMITE | B31: PMO | C31: Prioridades de remediação para o Comitê de Sócios | D31: =COUNTA(PMO_COMITE!B5:B29) -> 25
A32: LEG_ART57 | B32: Legislação | C32: Decreto 11.129/2022, art. 57 × perguntas | D32: =COUNTA(LEG_ART57!A22:A244) -> 223
A33: LEG_LEGISLACAO | B33: Legislação | C33: Legislação, guias e regras que sustentam o portal | D33: =COUNTA(LEG_LEGISLACAO!A5:A34) -> 30
A35: Como usar: ajuste RISCO_PARAMETROS; edite P e I em RISCO_MATRIZ_17; ligue cenários em RISCO_ESTRESSE; acompanhe o PMO_PLANO; informe o % atendido por área e marque ações (PMO_BIBLIOTECA_25, coluna S) em SIM_PROETICA.
A36: Células azuis sobre amarelo são editáveis; as demais são fórmulas ou dados do portal.
A37: Agentes: o portal configura os agentes por tipo de revisor, testes e critério; as abas AG_* materializam um agente por pergunta com essa configuração. Parecer é preliminar e a decisão é humana.
A38: Premissas que não vêm do portal: apetite de risco = 9, redução máxima de 1 ponto em P e em I por risco totalmente tratado, início do PMO em 05/10/2026 (RISCO_PARAMETROS).
A39: A pontuação simulada é estimativa de planejamento; não é nota nem homologação da CGU. As correspondências Pacto/Pró-Ética/ISO do portal não são homologadas.

Sheet TOTAIS
A1: Totais na sequência do portal: Perfil → Essenciais → Pacto → Pró-Ética → ISO → agentes → licitações → conflitos → riscos → PMO
A2: Todas as contagens são fórmulas sobre as abas de dados. A coluna Check deve mostrar OK.
A4: Etapa | B4: Item | C4: Perguntas / itens | D4: Pontos Pró-Ética | E4: Agentes | F4: Aba | G4: Check
A5: 0 · Perfil | B5: Perguntas de Perfil | C5: =COUNTA(0_PERFIL_108!A5:A112) -> 108 | E5: =COUNTA(AG_PERFIL_108!A5:A112) -> 108 | F5: 0_PERFIL_108 · AG_PERFIL_108 | G5: =IF(AND(C5=108,E5=108),"OK","REVISAR") -> OK
A6: I · Essenciais | B6: Conformidade: 10 Essenciais | C6: =COUNTA(I_ESSENCIAIS_10!A5:A14) -> 10 | D6: =SUM(I_ESSENCIAIS_10!G5:G14) -> 4.7 | E6: =COUNTIF(AG_CONFORMIDADE_223!$C$5:$C$227,"Essenciais") -> 10 | F6: I_ESSENCIAIS_10 | G6: =IF(AND(C6=10,E6=10),"OK","REVISAR") -> OK
A7: II · Pacto | B7: Conformidade: 76 QPE correlatas ao Pacto | C7: =COUNTA(II_PACTO_QPE_76!A5:A80) -> 76 | D7: =SUM(II_PACTO_QPE_76!G5:G80) -> 35.5 | E7: =COUNTIF(AG_CONFORMIDADE_223!$C$5:$C$227,"Pacto Brasil") -> 76 | F7: II_PACTO_QPE_76 | G7: =IF(AND(C7=76,E7=76),"OK","REVISAR") -> OK
A8: III · Pró-Ética | B8: Conformidade: 137 complementares | C8: =COUNTA(III_PROETICA_137!A5:A141) -> 137 | D8: =SUM(III_PROETICA_137!G5:G141) -> 59.8 | E8: =COUNTIF(AG_CONFORMIDADE_223!$C$5:$C$227,"Pró-Ética") -> 137 | F8: III_PROETICA_137 | G8: =IF(AND(C8=137,E8=137),"OK","REVISAR") -> OK
A9: Conformidade | B9: TOTAL da Conformidade (10 + 76 + 137) | C9: =SUM(C6:C8) -> 223 | D9: =SUM(D6:D8) -> 100 | E9: =SUM(E6:E8) -> 223 | F9: AG_CONFORMIDADE_223 | G9: =IF(AND(C9=223,E9=223,ROUND(D9,2)=100),"OK","REVISAR") -> OK
A10: II · Pacto | B10: Pacto Completo: itens do catálogo | C10: =COUNTA(II_PACTO_80_ITENS!A5:A84) -> 80 | F10: II_PACTO_80_ITENS | G10: =IF(C10=80,"OK","REVISAR") -> OK
A11: II · Pacto | B11: reaproveitáveis das Essenciais | C11: =COUNTIF(II_PACTO_80_ITENS!H5:H84,"Reaproveitável*") -> 11 | F11: II_PACTO_80_ITENS | G11: =IF(C11=11,"OK","REVISAR") -> OK
A12: II · Pacto | B12: complementos | C12: =COUNTA(II_PACTO_COMPL_69!A5:A73) -> 69 | F12: II_PACTO_COMPL_69 | G12: =IF(AND(C12=69,C11+C12=C10),"OK","REVISAR") -> OK
A13: IV · ISO | B13: Complemento ISO (parcial ou não previsto) | C13: =COUNTA(IV_ISO_COMPL_27!A5:A31) -> 27 | F13: IV_ISO_COMPL_27 | G13: =IF(C13=27,"OK","REVISAR") -> OK
A14: IV · ISO | B14: ISO reaproveitável (coberto pela CGU) | C14: =COUNTA(IV_ISO_REAPROV_24!A5:A28) -> 24 | F14: IV_ISO_REAPROV_24 | G14: =IF(C14=24,"OK","REVISAR") -> OK
A15: IV · ISO | B15: TOTAL ISO 37301/37001 | C15: =C13+C14 -> 51 | E15: =COUNTA(AG_ISO_51!A5:A55) -> 51 | F15: AG_ISO_51 | G15: =IF(AND(C15=51,E15=51),"OK","REVISAR") -> OK
A16: Licitações | B16: Checklist Lei 14.133/2021 | C16: =COUNTA(LIC_CHECKLIST_14133!A5:A16) -> 12 | F16: LIC_CHECKLIST_14133 | G16: =IF(C16>0,"OK","REVISAR") -> OK
A17: Licitações | B17: Perguntas marcadas "Licitações" | C17: =COUNTA(LIC_PERGUNTAS!A5:A23) -> 19 | F17: LIC_PERGUNTAS | G17: =IF(C17>0,"OK","REVISAR") -> OK
A18: Conflitos | B18: Agentes de conflito Perfil × Conformidade | C18: =COUNTA(CONF_MATRIZ_108!A5:A112) -> 108 | E18: =COUNTA(CONF_MATRIZ_108!A5:A112) -> 108 | F18: CONF_MATRIZ_108 | G18: =IF(C18=108,"OK","REVISAR") -> OK
A19: Conflitos | B19: Regras de conflito / dependência | C19: =COUNTA(CONF_REGRAS_42!A5:A46)&" / "&COUNTA(CONF_DEPENDENCIAS_23!A5:A27) -> 42 / 23 | F19: CONF_REGRAS_42 · CONF_DEPENDENCIAS_23
A20: Riscos | B20: Riscos na matriz (10 CGU + 7 ISO) | C20: =COUNTA(RISCO_MATRIZ_17!A5:A21) -> 17 | F20: RISCO_MATRIZ_17 | G20: =IF(C20=17,"OK","REVISAR") -> OK
A21: PMO | B21: Ações da biblioteca (18 CGU + 7 ISO) | C21: =COUNTA(PMO_BIBLIOTECA_25!A5:A29) -> 25 | F21: PMO_BIBLIOTECA_25 | G21: =IF(C21=25,"OK","REVISAR") -> OK
A22: Agentes | B22: TOTAL de agentes (Perfil + Conformidade + ISO + Conflitos) | E22: =E5+E9+E15+E18 -> 490 | F22: AG_* · CONF_MATRIZ_108
A24: Leitura: a Conformidade tem 223 perguntas = 10 Essenciais + 76 correlatas ao Pacto + 137 do Pró-Ética. O Pacto Completo tem 80 itens = 11 reaproveitáveis das Essenciais + 69 complementos (o item é reaproveitável quando seu QPE vinculado é uma Essencial). A ISO tem 51 requisitos = 27 complementos + 24 reaproveitáveis.

Sheet 0_PERFIL_108
A1: Etapa 0 · Perfil — 108 perguntas (quem é a empresa)
A2: Fonte: portal (DB.P). Agente = revisor de cada pergunta (detalhe na aba AG_PERFIL_108). Isos relacionadas: itens ISO que reaproveitam a resposta do Perfil.
A4: ID | B4: Grupo | C4: Pergunta | D4: Tipo de resposta | E4: Pergunta-pai (condição) | F4: Aplicável? | G4: Obrigatória? | H4: Evidência sugerida | I4: Agente | J4: Tipo de verificação | K4: Itens ISO relacionados
A5: DB1 | B5: Dados básicos | C5: Razão social registrada no CNPJ. | D5: text | F5: Sim | G5: Não | H5: Comprovante de inscrição e situação cadastral no CNPJ; ato societário ou histórico de alterações apenas para a informação societária solicitada. | I5: AG-PERF-DB1 | J5: CADASTRAL_REGULARIDADE
A6: DB2 | B6: Dados básicos | C6: Nome fantasia; informe não se aplica caso inexistente. | D6: text | F6: Sim | G6: Não | H6: Comprovante de inscrição e situação cadastral no CNPJ; ato societário ou histórico de alterações apenas para a informação societária solicitada. | I6: AG-PERF-DB2 | J6: CADASTRAL_REGULARIDADE
A7: DB3 | B7: Dados básicos | C7: Houve mudança de razão social nos últimos três anos? | D7: yn | F7: Sim | G7: Não | H7: Comprovante de inscrição e situação cadastral no CNPJ; ato societário ou histórico de alterações apenas para a informação societária solicitada. | I7: AG-PERF-DB3 | J7: CADASTRAL_REGULARIDADE
A8: DB3.1 | B8: Dados básicos | C8: Descreva as mudanças de razão social e suas datas. | D8: long | E8: DB3 | F8: Sim | G8: Não | H8: Comprovante de inscrição e situação cadastral no CNPJ; ato societário ou histórico de alterações apenas para a informação societária solicitada. | I8: AG-PERF-DB3.1 | J8: CADASTRAL_REGULARIDADE
A9: DB4 | B9: Dados básicos | C9: E-mail institucional da área de integridade. | D9: email | F9: Sim | G9: Não | H9: Somente resposta declaratória, salvo documento previsto no enunciado ou solicitado no formulário oficial. | I9: AG-PERF-DB4 | J9: DADO_DECLARATORIO
A10: DB5 | B10: Dados básicos | C10: CNPJ da pessoa jurídica participante. | D10: cnpj | F10: Sim | G10: Não | H10: Comprovante de inscrição e situação cadastral no CNPJ; ato societário ou histórico de alterações apenas para a informação societária solicitada. | I10: AG-PERF-DB5 | J10: CADASTRAL_REGULARIDADE
A11: DB6 | B11: Dados básicos | C11: Nome do representante da empresa. | D11: text | F11: Sim | G11: Não | H11: Ato de representação ou indicação do representante, apenas para conferência interna do responsável indicado. | I11: AG-PERF-DB6 | J11: DADO_DECLARATORIO
A12: DB7 | B12: Dados básicos | C12: Cargo do representante. | D12: text | F12: Sim | G12: Não | H12: Ato de representação ou indicação do representante, apenas para conferência interna do responsável indicado. | I12: AG-PERF-DB7 | J12: DADO_DECLARATORIO
A13: DB8 | B13: Dados básicos | C13: E-mail institucional do representante. | D13: email | F13: Sim | G13: Não | H13: Somente resposta declaratória, salvo documento previsto no enunciado ou solicitado no formulário oficial. | I13: AG-PERF-DB8 | J13: DADO_DECLARATORIO
A14: DB9 | B14: Dados básicos | C14: Telefone do representante. | D14: tel | F14: Sim | G14: Não | H14: Somente resposta declaratória, salvo documento previsto no enunciado ou solicitado no formulário oficial. | I14: AG-PERF-DB9 | J14: DADO_DECLARATORIO
A15: DB10 | B15: Dados básicos | C15: E-mail restrito para esclarecimentos sigilosos à CGU. | D15: email | F15: Sim | G15: Não | H15: Somente resposta declaratória, salvo documento previsto no enunciado ou solicitado no formulário oficial. | I15: AG-PERF-DB10 | J15: DADO_DECLARATORIO
A16: EA1 | B16: Estrutura e atividade econômica | C16: Principal setor de atividade econômica da empresa (faixa CNAE). | D16: text | F16: Sim | G16: Não | H16: Cadastro CNPJ e/ou ato constitutivo que identifique o setor, a atividade, a natureza societária ou a sede perguntada. | I16: AG-PERF-EA1 | J16: CADASTRAL_REGULARIDADE | K16: ISO-01
A17: EA2 | B17: Estrutura e atividade econômica | C17: CNAE principal, com sete dígitos. | D17: cnae | F17: Sim | G17: Não | H17: Cadastro CNPJ e/ou ato constitutivo que identifique o setor, a atividade, a natureza societária ou a sede perguntada. | I17: AG-PERF-EA2 | J17: CADASTRAL_REGULARIDADE
A18: EA3 | B18: Estrutura e atividade econômica | C18: Demais atividades econômicas desempenhadas. | D18: long | F18: Sim | G18: Não | H18: Cadastro CNPJ e/ou ato constitutivo que identifique o setor, a atividade, a natureza societária ou a sede perguntada. | I18: AG-PERF-EA3 | J18: CADASTRAL_REGULARIDADE | K18: ISO-01
A19: EA4 | B19: Estrutura e atividade econômica | C19: Tipo organizacional ou societário. | D19: text | F19: Sim | G19: Não | H19: Cadastro CNPJ e/ou ato constitutivo que identifique o setor, a atividade, a natureza societária ou a sede perguntada. | I19: AG-PERF-EA4 | J19: CADASTRAL_REGULARIDADE
A20: EA5 | B20: Estrutura e atividade econômica | C20: Porte da empresa segundo o faturamento anual. | D20: porte | F20: Sim | G20: Não | H20: Demonstração contábil ou apuração do faturamento no período-base que sustente a faixa informada. | I20: AG-PERF-EA5 | J20: DADO_QUANTITATIVO | K20: ISO-01
A21: EA6 | B21: Estrutura e atividade econômica | C21: Faixa do faturamento anual da empresa. | D21: text | F21: Sim | G21: Não | H21: Demonstração contábil ou apuração do faturamento no período-base que sustente a faixa informada. | I21: AG-PERF-EA6 | J21: DADO_QUANTITATIVO
A22: EA7 | B22: Estrutura e atividade econômica | C22: A empresa tem capital aberto? | D22: yn | F22: Sim | G22: Não | H22: Cadastro CNPJ e/ou ato constitutivo que identifique o setor, a atividade, a natureza societária ou a sede perguntada. | I22: AG-PERF-EA7 | J22: CADASTRAL_REGULARIDADE
A23: EA8 | B23: Estrutura e atividade econômica | C23: Unidades da Federação em que a empresa atua. | D23: long | F23: Sim | G23: Não | H23: Somente resposta declaratória, salvo documento previsto no enunciado ou solicitado no formulário oficial. | I23: AG-PERF-EA8 | J23: DADO_DECLARATORIO | K23: ISO-01; ISO-04
A24: EA9 | B24: Estrutura e atividade econômica | C24: Unidade da Federação da sede. | D24: uf | F24: Sim | G24: Não | H24: Cadastro CNPJ e/ou ato constitutivo que identifique o setor, a atividade, a natureza societária ou a sede perguntada. | I24: AG-PERF-EA9 | J24: CADASTRAL_REGULARIDADE
A25: EA10 | B25: Estrutura e atividade econômica | C25: A empresa atua fora do Brasil? | D25: yn | F25: Sim | G25: Não | H25: Ato societário, organograma do grupo ou instrumento da operação apenas se a situação descrita ocorreu. | I25: AG-PERF-EA10 | J25: DADO_DECLARATORIO | K25: ISO-01; ISO-06
A26: EA10.1 | B26: Estrutura e atividade econômica | C26: Países em que possui operações. | D26: long | E26: EA10 | F26: Sim | G26: Não | H26: Ato societário, organograma do grupo ou instrumento da operação apenas se a situação descrita ocorreu. | I26: AG-PERF-EA10.1 | J26: DADO_DECLARATORIO
A27: EA10.2 | B27: Estrutura e atividade econômica | C27: Legislação anticorrupção estrangeira aplicável às operações. | D27: long | E27: EA10 | F27: Sim | G27: Não | H27: Ato societário, organograma do grupo ou instrumento da operação apenas se a situação descrita ocorreu. | I27: AG-PERF-EA10.2 | J27: DADO_DECLARATORIO
A28: EA11 | B28: Estrutura e atividade econômica | C28: Possui subsidiárias em outros países? | D28: yn | F28: Sim | G28: Não | H28: Ato societário, organograma do grupo ou instrumento da operação apenas se a situação descrita ocorreu. | I28: AG-PERF-EA11 | J28: DADO_DECLARATORIO
A29: EA12 | B29: Estrutura e atividade econômica | C29: Integra grupo econômico? | D29: yn | F29: Sim | G29: Não | H29: Ato societário, organograma do grupo ou instrumento da operação apenas se a situação descrita ocorreu. | I29: AG-PERF-EA12 | J29: DADO_DECLARATORIO | K29: ISO-01; ISO-03; ISO-04
A30: EA12.1 | B30: Estrutura e atividade econômica | C30: Nome do grupo econômico. | D30: text | E30: EA12 | F30: Sim | G30: Não | H30: Ato societário, organograma do grupo ou instrumento da operação apenas se a situação descrita ocorreu. | I30: AG-PERF-EA12.1 | J30: DADO_DECLARATORIO
A31: EA12.2 | B31: Estrutura e atividade econômica | C31: Empresas do grupo cobertas pelo programa de integridade. | D31: long | E31: EA12 | F31: Sim | G31: Não | H31: Ato societário, organograma do grupo ou instrumento da operação apenas se a situação descrita ocorreu. | I31: AG-PERF-EA12.2 | J31: DADO_DECLARATORIO | K31: ISO-04
A32: EA12.3 | B32: Estrutura e atividade econômica | C32: Posição societária da empresa no grupo e principais integrantes e países. | D32: long | E32: EA12 | F32: Sim | G32: Não | H32: Ato societário, organograma do grupo ou instrumento da operação apenas se a situação descrita ocorreu. | I32: AG-PERF-EA12.3 | J32: DADO_DECLARATORIO
A33: EA13 | B33: Estrutura e atividade econômica | C33: Estrutura organizacional, órgãos e linhas de reporte. | D33: long | F33: Sim | G33: Não | H33: Organograma ou documento organizacional vigente, se disponível. | I33: AG-PERF-EA13 | J33: DADO_DECLARATORIO | K33: ISO-01
A34: EA14 | B34: Estrutura e atividade econômica | C34: Houve fusões, aquisições ou outras operações societárias entre 2022 e 2025? | D34: yn | F34: Sim | G34: Não | H34: Ato societário, organograma do grupo ou instrumento da operação apenas se a situação descrita ocorreu. | I34: AG-PERF-EA14 | J34: DADO_DECLARATORIO
A35: EA14.1 | B35: Estrutura e atividade econômica | C35: Detalhes e datas das operações societárias realizadas entre 2022 e 2025. | D35: long | E35: EA14 | F35: Sim | G35: Não | H35: Ato societário, organograma do grupo ou instrumento da operação apenas se a situação descrita ocorreu. | I35: AG-PERF-EA14.1 | J35: GOVERNANCA
A36: EA15 | B36: Estrutura e atividade econômica | C36: Houve consórcios, joint ventures ou outras parcerias entre 2022 e 2025? | D36: yn | F36: Sim | G36: Não | H36: Ato societário, organograma do grupo ou instrumento da operação apenas se a situação descrita ocorreu. | I36: AG-PERF-EA15 | J36: DADO_DECLARATORIO
A37: EA15.1 | B37: Estrutura e atividade econômica | C37: Descreva as parcerias firmadas entre 2022 e 2025. | D37: long | E37: EA15 | F37: Sim | G37: Não | H37: Ato societário, organograma do grupo ou instrumento da operação apenas se a situação descrita ocorreu. | I37: AG-PERF-EA15.1 | J37: DADO_DECLARATORIO
A38: EA16 | B38: Estrutura e atividade econômica | C38: Total de colaboradores, incluindo terceirizados, aprendizes e estagiários. | D38: int | F38: Sim | G38: Não | H38: Relatório de pessoal ou quantitativo consolidado referente ao período declarado; sem nomes pessoais desnecessários. | I38: AG-PERF-EA16 | J38: DADO_DECLARATORIO
A39: EA17 | B39: Estrutura e atividade econômica | C39: Quantidade de colaboradores em funções gerenciais. | D39: int | F39: Sim | G39: Não | H39: Relatório de pessoal ou quantitativo consolidado referente ao período declarado; sem nomes pessoais desnecessários. | I39: AG-PERF-EA17 | J39: DADO_QUANTITATIVO
A40: EA18 | B40: Estrutura e atividade econômica | C40: Quantidade de colaboradores em funções administrativas. | D40: int | F40: Sim | G40: Não | H40: Relatório de pessoal ou quantitativo consolidado referente ao período declarado; sem nomes pessoais desnecessários. | I40: AG-PERF-EA18 | J40: DADO_QUANTITATIVO
A41: EA19 | B41: Estrutura e atividade econômica | C41: Quantidade de colaboradores em funções operacionais. | D41: int | F41: Sim | G41: Não | H41: Relatório de pessoal ou quantitativo consolidado referente ao período declarado; sem nomes pessoais desnecessários. | I41: AG-PERF-EA19 | J41: DADO_QUANTITATIVO
...

Sheet I_ESSENCIAIS_10
A1: Etapa I · Pacto Essencial — 10 medidas mínimas (perguntas QPE próprias)
A2: Fonte: portal (DB.Q trilha Essenciais + DB.ESS). A coluna "Medida essencial" liga a pergunta ao item ITP e ao item do Pacto (PB).
A4: ID | B4: Nº formulário | C4: Trilha | D4: Área | E4: Pergunta | F4: Evidência sugerida | G4: Peso (pts) | H4: Agente | I4: Tipo de verificação | J4: Natureza | K4: Janela | L4: Itens do Pacto | M4: Itens ISO | N4: Incisos art. 57 | O4: Licitações? | P4: Medida essencial (ITP)
A5: QPE-006 | B5: 2.2 | C5: Essenciais | D5: Comprometimento da Alta Direção | E5: A alta direção da empresa supervisiona a implantação e a aplicação do programa de integridade, por meio do recebimento e avaliação de relatórios periódicos de acompanhamento das atividades relacionadas ao programa de integridade, inclusive de suas controladas/subsidiárias, quando for o caso? Se sim, indicar a forma e a periodicidade com que a alta direção participa da supervisão do programa de integridade, bem como descrever o tipo e o conteúdo dos documentos que lhe foram apresentados para subsidiar suas decisões. | F5: Documentos que indiquem a forma como a alta direção participou da supervisão da implantação e da aplicação do programa de integridade, tais como: − documentos que comprovem a frequência das ações de supervisão do programa pela alta direção; − atas de reuniões entre membros da alta direção e responsáveis pelas atividades do programa de integridade; − e-mails, apresentações feitas em reuniões, registros de frequência das ações de supervisão; − assinaturas de membros da alta direção em relatórios de atividades do programa de integridade. Inclua também, quando existente, a política ou norma interna de governança que formaliza o dever de supervisão da alta direção sobre o programa de integridade. | G5: 0.9 | H5: AG-FCG-QPE-006 | I5: GOVERNANCA | J5: Execução | K5: PERIODO | L5: 1.1; 2.2 | M5: ISO-08; ISO-44; ISO-47; ISO-48 | N5: I | P5: ITP-001 / PB-001
A6: QPE-024 | B6: 4.1 | C6: Essenciais | D6: Instância Responsável pelo Programa | E6: A empresa possui área específica ou pessoa responsável pela aplicação do programa de integridade? Se sim, informar a data em que a área foi instituída ou em que a pessoa responsável foi contratada/designada para a função, o currículo do atual responsável pela instância interna, o processo de seleção do atual responsável pela instância interna, e o órgão competente por sua contratação e eventual demissão. | F6: Documentos que comprovem a existência de uma instância interna (seja uma área ou pessoa designada) responsável pela implementação, fiscalização e monitoramento contínuo do programa de integridade no Brasil, tais como: políticas, regimento interno, estatuto, job description etc. Não serão considerados como área específica órgãos colegiados (comitês, conselhos etc.). Inclua também, quando existente, a política ou diretriz interna que formaliza as atribuições e a autonomia da instância responsável pelo programa (além do regimento/estatuto já solicitado). | G6: 1 | H6: AG-FCG-QPE-024 | I6: GOVERNANCA | J6: Desenho | K6: VIGENTE | L6: 4.1 | M6: ISO-14 | N6: IX | P6: ITP-002 / PB-009
A7: QPE-041 | B7: 6.2 | C7: Essenciais | D7: Gestão de Riscos para a Integridade | E7: No período avaliado, a empresa realizou análise de riscos para integridade, incluindo uma análise que contemple expressamente riscos relacionados a corrupção e fraude? (*Medida mínima prevista no art. 14 do Regulamento, de caráter obrigatório) | F7: Evidências da análise de riscos para integridade, relacionadas à corrupção e fraude, realizada pela própria empresa ou por terceiros,; POL-06 — Due Diligence de Terceiros Inclua também a política ou diretriz de gestão de riscos de integridade aplicável, quando existente, além da própria análise de riscos. | G7: 1 | H7: AG-FCG-QPE-041 | I7: RISCOS_TERCEIROS | J7: Execução | K7: PERIODO | L7: 5.1 | M7: ISO-07 | N7: V | P7: ITP-003 / PB-011
A8: QPE-051 | B8: 7.1 | C8: Essenciais | D8: Código de Ética, Políticas e Procedimentos | E8: A empresa possui Código de Ética e Conduta, ou documento equivalente, disponível em português? (Medida mínima prevista no art. 14 do Regulamento, de caráter obrigatório) | F8: Código de Ética, ou documento equivalente, em língua portuguesa.; POL-01 — Código de Ética Inclua também eventuais diretrizes ou guias complementares ao Código de Ética (ex.: guia de aplicação, FAQ interno), quando existentes. | G8: 0.1 | H8: AG-FCG-QPE-051 | I8: NORMATIVO | J8: Desenho | K8: VIGENTE | L8: 6.1 | M8: ISO-12 | N8: II | P8: ITP-004 / PB-016
A9: QPE-107 | B9: 11.3.1 | C9: Essenciais | D9: Treinamento e Comunicação | E9: No período avaliado, a empresa realizou treinamentos: direcionados a todos os empregados, abordando conteúdo geral do programa de integridade, como Código de Ética, canais de denúncia e política anticorrupção? | F9: Listas de presenças acompanhadas de materiais de estudo, links de acesso a treinamentos online ou registros de frequência e participação que demonstrem: o treinamento geral dos colaboradores nos temas fundamentais do programa de integridade (código de ética, canais de denúncia e política anticorrupção);; POL-01 — Código de Ética Inclua também, quando existente, a política ou diretriz de treinamento e capacitação em integridade que rege o conteúdo e a periodicidade das ações formativas. | G9: 0.5 | H9: AG-FCG-QPE-107 | I9: TREINAMENTO | J9: Execução | K9: PERIODO | L9: 8.1 | M9: ISO-26; ISO-27 | N9: IV | P9: ITP-006 / PB-036
A10: QPE-128 | B10: 12.3.7 | C10: Essenciais | D10: Treinamento e Comunicação | E10: As ações de comunicação realizadas pela empresa no período avaliado: foram realizadas por diferentes meios, para alcançar o público interno da empresa em toda sua diversidade? | F10: Correlacionar os diversos públicos de empregados da empresa com os meios de comunicação utilizados (e-mails, vídeos, cartazes, folders, registros da intranet, site etc.), com o objetivo de avaliar se todo o público interno foi alcançado. Inclua também, quando existente, a política ou diretriz de comunicação interna sobre integridade que orienta essas ações. | G10: 0.7 | H10: AG-FCG-QPE-128 | I10: PUBLICACAO_COMUNICACAO | J10: Execução | K10: PERIODO | L10: 9.1 | M10: ISO-28 | N10: IV | P10: ITP-007 / PB-039
A11: QPE-169 | B11: 19.1 | C11: Essenciais | D11: Canal de Denúncia e Medidas Disciplinares | E11: *A empresa possui canais para realização de denúncias, disponíveis em português? | F11: Link do site e caminho de navegação desde a página inicial até o canal de denúncias. Inclua também a política ou regulamento interno do canal de denúncias (sigilo, apuração e vedação a retaliação), quando existente, além do link de acesso. | G11: 0.1 | H11: AG-FCG-QPE-169 | I11: PUBLICACAO_COMUNICACAO | J11: Desenho | K11: VIGENTE | L11: 14.1 | M11: ISO-39 | N11: X | P11: ITP-008 / PB-053
A12: QPE-218 | B12: 23.2 | C12: Essenciais | D12: Transparência e Responsabilidade Socioambiental | E12: Existe uma seção específica no site da empresa que reúna as informações sobre o programa de integridade? | F12: Informar tanto o link de acesso quanto o caminho da página inicial do site da empresa até a seção específica no site da empresa que reúna as informações sobre o programa de integridade. Inclua também, quando existente, a diretriz ou guia de comunicação institucional que rege o conteúdo publicado sobre o programa de integridade. | G12: 0.2 | H12: AG-FCG-QPE-218 | I12: EXECUCAO_CONTROLE | J12: Publicação | K12: VIGENTE | L12: 19.1 | M12: ISO-28 | P12: ITP-009 / PB-072
A13: QPE-221 | B13: 24.3 | C13: Essenciais | D13: Transparência e Responsabilidade Socioambiental | E13: A empresa possui políticas e procedimentos para o tratamento e a destinação sustentável de resíduos sólidos, efluentes e gases gerados em suas áreas administrativas e/ou produtivas, considerando os impactos ambientais de suas atividades? | F13: Política, norma ou procedimento formal, aprovado pela direção da empresa e amplamente divulgado, que disponha sobre regras de tratamento e destino de resíduos sólidos e efluentes, considerando seus impactos no meio ambiente, sua mitigação e potencialidades de uso sustentável. Inclua também eventuais guias operacionais complementares à política ambiental, quando existentes, além da própria política já solicitada. | G13: 0.1 | H13: AG-FCG-QPE-221 | I13: GOVERNANCA | J13: Desenho | K13: VIGENTE | L13: 18.1 | P13: ITP-010 / PB-069
A14: QPE-073 | B14: 9.1.1 | C14: Essenciais | D14: Código de Ética, Políticas e Procedimentos | E14: A empresa possui políticas e procedimentos de integridade que: vedam expressamente a concessão de vantagens indevidas, econômicas ou não, a agentes públicos? | F14: Políticas, regras, orientações e/ou procedimentos (indicar a seção e a página) que: vedam expressamente a concessão de vantagens indevidas, econômicas ou não, a agentes públicos;; POL-05 — Relacionamento com o Setor Público Inclua também eventuais guias práticos ou diretrizes complementares sobre relacionamento com agentes públicos, quando existentes, além da própria política. | G14: 0.1 | H14: AG-FCG-QPE-073 | I14: NORMATIVO | J14: Desenho | K14: VIGENTE | L14: 7.1.1 | M14: ISO-12; ISO-31 | N14: II; VIII | O14: Sim | P14: ITP-005 / PB-026
E16: Total de perguntas / pontos | F16: =COUNTA(A5:A14) -> 10 | G16: =SUM(G5:G14) -> 4.7

Sheet II_PACTO_80_ITENS
A1: Etapa II · Pacto Completo — catálogo de 80 itens (11 reaproveitáveis das Essenciais + 69 complementos)
A2: Fonte: portal (DB.PACTO). Regra do portal: item cujo QPE vinculado é uma Essencial = reaproveitável; os demais = complemento. Redação sintética a validar no SAMPI.
A4: ID | B4: Nº | C4: Área | D4: Item do Pacto | E4: Medida essencial? | F4: Perguntas QPE vinculadas | G4: Medida (ITP) | H4: Classe | I4: Fonte
A5: PB-001 | B5: 1.1 | C5: Área I | D5: Os membros da alta direção apoiam de forma inequívoca a implementação de medidas de integridade? | E5: Sim | F5: QPE-006 | G5: ITP-001 | H5: Reaproveitável (Essencial) | I5: DIM_PACTO do modelo Simples GRC; redação sintética a validar no SAMPI
A6: PB-002 | B6: 1.2 | C6: Área I | D6: Os membros manifestam publicamente o apoio à integridade empresarial de forma personalizada? | E6: Não | F6: QPE-014 | H6: Complemento | I6: DIM_PACTO do modelo Simples GRC; redação sintética a validar no SAMPI
A7: PB-003 | B7: 1.3 | C7: Área I | D7: As mensagens incentivam conduta ética e tolerância zero com corrupção? | E7: Não | F7: QPE-019 | H7: Complemento | I7: DIM_PACTO do modelo Simples GRC; redação sintética a validar no SAMPI
A8: PB-004 | B8: 1.4 | C8: Área I | D8: As mensagens promovem preservação ambiental e respeito aos direitos humanos e trabalhistas? | E8: Não | F8: QPE-013; QPE-020 | H8: Complemento | I8: DIM_PACTO do modelo Simples GRC; redação sintética a validar no SAMPI
A9: PB-005 | B9: 2.1 | C9: Área I | D9: A aprovação das principais políticas de integridade é feita pelas elevadas instâncias decisórias? | E9: Não | F9: QPE-005 | H9: Complemento | I9: DIM_PACTO do modelo Simples GRC; redação sintética a validar no SAMPI
A10: PB-006 | B10: 2.2 | C10: Área I | D10: A alta direção supervisiona implantação mediante recebimento de relatórios periódicos? | E10: Não | F10: QPE-006 | H10: Reaproveitável (Essencial) | I10: DIM_PACTO do modelo Simples GRC; redação sintética a validar no SAMPI
A11: PB-007 | B11: 3.1 | C11: Área I | D11: Adota formalmente critérios de integridade para seleção de candidatos à alta direção? | E11: Não | F11: QPE-001; QPE-002 | H11: Complemento | I11: DIM_PACTO do modelo Simples GRC; redação sintética a validar no SAMPI
A12: PB-008 | B12: 3.2 | C12: Área I | D12: Remuneração variável está condicionada a indicadores relacionados à aplicação de medidas? | E12: Não | F12: QPE-004 | H12: Complemento | I12: DIM_PACTO do modelo Simples GRC; redação sintética a validar no SAMPI
A13: PB-009 | B13: 4.1 | C13: Área II | D13: A empresa possui instância interna responsável pela aplicação do programa de integridade? | E13: Sim | F13: QPE-024 | G13: ITP-002 | H13: Reaproveitável (Essencial) | I13: DIM_PACTO do modelo Simples GRC; redação sintética a validar no SAMPI
A14: PB-010 | B14: 4.2 | C14: Área II | D14: A instância está formalmente constituída com atribuições em documento aprovado? | E14: Não | F14: QPE-025 | H14: Complemento | I14: DIM_PACTO do modelo Simples GRC; redação sintética a validar no SAMPI
A15: PB-011 | B15: 5.1 | C15: Área III | D15: Realizou análise de riscos nos últimos 24 meses contemplando expressamente corrupção e fraude? | E15: Sim | F15: QPE-041 | G15: ITP-003 | H15: Reaproveitável (Essencial) | I15: DIM_PACTO do modelo Simples GRC; redação sintética a validar no SAMPI
A16: PB-012 | B16: 5.2 | C16: Área III | D16: A análise contempla classificação dos riscos por probabilidade e impacto? | E16: Não | F16: QPE-042 | H16: Complemento | I16: DIM_PACTO do modelo Simples GRC; redação sintética a validar no SAMPI
A17: PB-013 | B17: 5.3 | C17: Área III | D17: Estabeleceu medidas de mitigação com prazos e responsáveis definidos? | E17: Não | F17: QPE-043; QPE-044 | H17: Complemento | I17: DIM_PACTO do modelo Simples GRC; redação sintética a validar no SAMPI
A18: PB-014 | B18: 5.4 | C18: Área III | D18: Possui normativo sobre gestão de riscos prevendo reavaliação periódica? | E18: Não | F18: QPE-037; QPE-038 | H18: Complemento | I18: DIM_PACTO do modelo Simples GRC; redação sintética a validar no SAMPI
A19: PB-015 | B19: 5.5 | C19: Área III | D19: Identifica e trata riscos relacionados a impactos ambientais de suas atividades? | E19: Não | F19: QPE-050 | H19: Complemento | I19: DIM_PACTO do modelo Simples GRC; redação sintética a validar no SAMPI
A20: PB-016 | B20: 6.1 | C20: Área IV | D20: Possui Código de Ética e Conduta ou equivalente em português? | E20: Sim | F20: QPE-051 | G20: ITP-004 | H20: Reaproveitável (Essencial) | I20: DIM_PACTO do modelo Simples GRC; redação sintética a validar no SAMPI
A21: PB-017 | B21: 6.2.1 | C21: Área IV | D21: O código foi formalmente aprovado pela alta direção? | E21: Não | F21: QPE-052 | H21: Complemento | I21: DIM_PACTO do modelo Simples GRC; redação sintética a validar no SAMPI
A22: PB-018 | B22: 6.2.2 | C22: Área IV | D22: Inclui expressamente ética e integridade entre princípios ou valores? | E22: Não | F22: QPE-053 | H22: Complemento | I22: DIM_PACTO do modelo Simples GRC; redação sintética a validar no SAMPI
A23: PB-019 | B23: 6.2.3 | C23: Área IV | D23: Está alinhado com legislação anticorrupção brasileira, vedando corrupção? | E23: Não | F23: QPE-055 | H23: Complemento | I23: DIM_PACTO do modelo Simples GRC; redação sintética a validar no SAMPI
A24: PB-020 | B24: 6.2.4 | C24: Área IV | D24: Expressa compromisso com respeito aos direitos humanos? | E24: Não | H24: Complemento | I24: DIM_PACTO do modelo Simples GRC; redação sintética a validar no SAMPI
A25: PB-021 | B25: 6.2.5 | C25: Área IV | D25: Expressa compromisso com direitos trabalhistas e salário justo? | E25: Não | H25: Complemento | I25: DIM_PACTO do modelo Simples GRC; redação sintética a validar no SAMPI
A26: PB-022 | B26: 6.2.6 | C26: Área IV | D26: Expressa compromisso com preservação ambiental e desenvolvimento sustentável? | E26: Não | F26: QPE-061 | H26: Complemento | I26: DIM_PACTO do modelo Simples GRC; redação sintética a validar no SAMPI
A27: PB-023 | B27: 6.2.7 | C27: Área IV | D27: Estabelece condutas permitidas e proibidas pela empresa? | E27: Não | F27: QPE-056 | H27: Complemento | I27: DIM_PACTO do modelo Simples GRC; redação sintética a validar no SAMPI
A28: PB-024 | B28: 6.2.8 | C28: Área IV | D28: Menciona possibilidade de sanções para violações, inclusive para alta direção? | E28: Não | F28: QPE-062 | H28: Complemento | I28: DIM_PACTO do modelo Simples GRC; redação sintética a validar no SAMPI
A29: PB-025 | B29: 6.3 | C29: Área IV | D29: O código encontra-se disponível na página institucional ou redes sociais? | E29: Não | F29: QPE-066 | H29: Complemento | I29: DIM_PACTO do modelo Simples GRC; redação sintética a validar no SAMPI
A30: PB-026 | B30: 7.1.1 | C30: Área IV | D30: Políticas vedam expressamente concessão de vantagens econômicas a agentes públicos? | E30: Sim | F30: QPE-073 | G30: ITP-005 | H30: Reaproveitável (Essencial) | I30: DIM_PACTO do modelo Simples GRC; redação sintética a validar no SAMPI
A31: PB-027 | B31: 7.1.2 | C31: Área IV | D31: Tratam do oferecimento de presentes, brindes e hospitalidades a agentes públicos? | E31: Não | F31: QPE-074 | H31: Complemento | I31: DIM_PACTO do modelo Simples GRC; redação sintética a validar no SAMPI
A32: PB-028 | B32: 7.1.3 | C32: Área IV | D32: Tratam prevenção de conflito de interesses com Administração Pública? | E32: Não | F32: QPE-075 | H32: Complemento | I32: DIM_PACTO do modelo Simples GRC; redação sintética a validar no SAMPI
A33: PB-029 | B33: 7.1.4 | C33: Área IV | D33: Estabelecem orientações sobre reuniões e interações com agentes públicos? | E33: Não | F33: QPE-076 | H33: Complemento | I33: DIM_PACTO do modelo Simples GRC; redação sintética a validar no SAMPI
A34: PB-030 | B34: 7.1.5 | C34: Área IV | D34: Tratam realização de doação e patrocínio ou informam que não realiza? | E34: Não | F34: QPE-078 | H34: Complemento | I34: DIM_PACTO do modelo Simples GRC; redação sintética a validar no SAMPI
A35: PB-031 | B35: 7.1.6 | C35: Área IV | D35: Estabelecem orientações específicas para prevenção de fraudes em licitações? | E35: Não | H35: Complemento | I35: DIM_PACTO do modelo Simples GRC; redação sintética a validar no SAMPI
A36: PB-032 | B36: 7.1.7 | C36: Área IV | D36: Estabelecem orientações para prevenção de fraudes em execução de contratos? | E36: Não | F36: QPE-093 | H36: Complemento | I36: DIM_PACTO do modelo Simples GRC; redação sintética a validar no SAMPI
A37: PB-033 | B37: 7.1.8 | C37: Área IV | D37: Vedam expressamente exploração de trabalho infantil? | E37: Não | H37: Complemento | I37: DIM_PACTO do modelo Simples GRC; redação sintética a validar no SAMPI
A38: PB-034 | B38: 7.1.9 | C38: Área IV | D38: Vedam expressamente trabalho escravo ou em condições análogas? | E38: Não | H38: Complemento | I38: DIM_PACTO do modelo Simples GRC; redação sintética a validar no SAMPI
A39: PB-035 | B39: 7.2 | C39: Área IV | D39: As políticas e procedimentos foram aplicados periodicamente nos últimos 12 meses? | E39: Não | F39: QPE-083 | H39: Complemento | I39: DIM_PACTO do modelo Simples GRC; redação sintética a validar no SAMPI
A40: PB-036 | B40: 8.1 | C40: Área V | D40: Realizou treinamentos nos últimos 12 meses abordando conteúdo de integridade? | E40: Sim | F40: QPE-107 | G40: ITP-006 | H40: Reaproveitável (Essencial) | I40: DIM_PACTO do modelo Simples GRC; redação sintética a validar no SAMPI
A41: PB-037 | B41: 8.2 | C41: Área V | D41: Os treinamentos são planejados considerando características de cada público-alvo? | E41: Não | F41: QPE-103 | H41: Complemento | I41: DIM_PACTO do modelo Simples GRC; redação sintética a validar no SAMPI
...

Sheet II_PACTO_COMPL_69
A1: Etapa II · Complemento do Pacto — os 69 itens que não vêm das Essenciais
A2: Fonte: portal (DB.PACTO filtrado pela regra acima). Nº das perguntas QPE vem do formulário.
A4: ID | B4: Nº | C4: Área | D4: Item do Pacto | E4: Perguntas QPE vinculadas | F4: Nº no formulário | G4: Fonte
A5: PB-002 | B5: 1.2 | C5: Área I | D5: Os membros manifestam publicamente o apoio à integridade empresarial de forma personalizada? | E5: QPE-014 | F5: 3.1 | G5: DIM_PACTO do modelo Simples GRC; redação sintética a validar no SAMPI
A6: PB-003 | B6: 1.3 | C6: Área I | D6: As mensagens incentivam conduta ética e tolerância zero com corrupção? | E6: QPE-019 | F6: 3.2.5 | G6: DIM_PACTO do modelo Simples GRC; redação sintética a validar no SAMPI
A7: PB-004 | B7: 1.4 | C7: Área I | D7: As mensagens promovem preservação ambiental e respeito aos direitos humanos e trabalhistas? | E7: QPE-013; QPE-020 | F7: 2.5; 3.2.6 | G7: DIM_PACTO do modelo Simples GRC; redação sintética a validar no SAMPI
A8: PB-005 | B8: 2.1 | C8: Área I | D8: A aprovação das principais políticas de integridade é feita pelas elevadas instâncias decisórias? | E8: QPE-005 | F8: 2.1 | G8: DIM_PACTO do modelo Simples GRC; redação sintética a validar no SAMPI
A9: PB-007 | B9: 3.1 | C9: Área I | D9: Adota formalmente critérios de integridade para seleção de candidatos à alta direção? | E9: QPE-001; QPE-002 | F9: 1.1; 1.2 | G9: DIM_PACTO do modelo Simples GRC; redação sintética a validar no SAMPI
A10: PB-008 | B10: 3.2 | C10: Área I | D10: Remuneração variável está condicionada a indicadores relacionados à aplicação de medidas? | E10: QPE-004 | F10: 1.4 | G10: DIM_PACTO do modelo Simples GRC; redação sintética a validar no SAMPI
A11: PB-010 | B11: 4.2 | C11: Área II | D11: A instância está formalmente constituída com atribuições em documento aprovado? | E11: QPE-025 | F11: 4.2.1 | G11: DIM_PACTO do modelo Simples GRC; redação sintética a validar no SAMPI
A12: PB-012 | B12: 5.2 | C12: Área III | D12: A análise contempla classificação dos riscos por probabilidade e impacto? | E12: QPE-042 | F12: 6.3.1 | G12: DIM_PACTO do modelo Simples GRC; redação sintética a validar no SAMPI
A13: PB-013 | B13: 5.3 | C13: Área III | D13: Estabeleceu medidas de mitigação com prazos e responsáveis definidos? | E13: QPE-043; QPE-044 | F13: 6.3.2; 6.3.3 | G13: DIM_PACTO do modelo Simples GRC; redação sintética a validar no SAMPI
A14: PB-014 | B14: 5.4 | C14: Área III | D14: Possui normativo sobre gestão de riscos prevendo reavaliação periódica? | E14: QPE-037; QPE-038 | F14: 6.1; 6.1.1 | G14: DIM_PACTO do modelo Simples GRC; redação sintética a validar no SAMPI
A15: PB-015 | B15: 5.5 | C15: Área III | D15: Identifica e trata riscos relacionados a impactos ambientais de suas atividades? | E15: QPE-050 | F15: 6.5 | G15: DIM_PACTO do modelo Simples GRC; redação sintética a validar no SAMPI
... A18: PB-019 | B18: 6.2.3 | C18: Área IV | D18: Está alinhado com legislação anticorrupção brasileira, vedando corrupção? | E18: QPE-055 | F18: 7.2.4 | G18: DIM_PACTO do modelo Simples GRC; redação sintética a validar no SAMPI
A19: PB-020 | B19: 6.2.4 | C19: Área IV | D19: Expressa compromisso com respeito aos direitos humanos? | G19: DIM_PACTO do modelo Simples GRC; redação sintética a validar no SAMPI
A20: PB-021 | B20: 6.2.5 | C20: Área IV | D20: Expressa compromisso com direitos trabalhistas e salário justo? | G20: DIM_PACTO do modelo Simples GRC; redação sintética a validar no SAMPI
A21: PB-022 | B21: 6.2.6 | C21: Área IV | D21: Expressa compromisso com preservação ambiental e desenvolvimento sustentável? | E21: QPE-061 | F21: 7.2.10 | G21: DIM_PACTO do modelo Simples GRC; redação sintética a validar no SAMPI
A22: PB-023 | B22: 6.2.7 | C22: Área IV | D22: Estabelece condutas permitidas e proibidas pela empresa? | E22: QPE-056 | F22: 7.2.5 | G22: DIM_PACTO do modelo Simples GRC; redação sintética a validar no SAMPI
A23: PB-024 | B23: 6.2.8 | C23: Área IV | D23: Menciona possibilidade de sanções para violações, inclusive para alta direção? | E23: QPE-062 | F23: 7.2.11 | G23: DIM_PACTO do modelo Simples GRC; redação sintética a validar no SAMPI
A24: PB-025 | B24: 6.3 | C24: Área IV | D24: O código encontra-se disponível na página institucional ou redes sociais? | E24: QPE-066 | F24: 7.3 | G24: DIM_PACTO do modelo Simples GRC; redação sintética a validar no SAMPI
A25: PB-027 | B25: 7.1.2 | C25: Área IV | D25: Tratam do oferecimento de presentes, brindes e hospitalidades a agentes públicos? | E25: QPE-074 | F25: 9.1.2 | G25: DIM_PACTO do modelo Simples GRC; redação sintética a validar no SAMPI
A26: PB-028 | B26: 7.1.3 | C26: Área IV | D26: Tratam prevenção de conflito de interesses com Administração Pública? | E26: QPE-075 | F26: 9.1.3 | G26: DIM_PACTO do modelo Simples GRC; redação sintética a validar no SAMPI
A27: PB-029 | B27: 7.1.4 | C27: Área IV | D27: Estabelecem orientações sobre reuniões e interações com agentes públicos? | E27: QPE-076 | F27: 9.1.4 | G27: DIM_PACTO do modelo Simples GRC; redação sintética a validar no SAMPI
A28: PB-030 | B28: 7.1.5 | C28: Área IV | D28: Tratam realização de doação e patrocínio ou informam que não realiza? | E28: QPE-078 | F28: 9.1.6 | G28: DIM_PACTO do modelo Simples GRC; redação sintética a validar no SAMPI
A29: PB-031 | B29: 7.1.6 | C29: Área IV | D29: Estabelecem orientações específicas para prevenção de fraudes em licitações? | G29: DIM_PACTO do modelo Simples GRC; redação sintética a validar no SAMPI
A30: PB-032 | B30: 7.1.7 | C30: Área IV | D30: Estabelecem orientações para prevenção de fraudes em execução de contratos? | E30: QPE-093 | F30: 10.3.1 | G30: DIM_PACTO do modelo Simples GRC; redação sintética a validar no SAMPI
A31: PB-033 | B31: 7.1.8 | C31: Área IV | D31: Vedam expressamente exploração de trabalho infantil? | G31: DIM_PACTO do modelo Simples GRC; redação sintética a validar no SAMPI
A32: PB-034 | B32: 7.1.9 | C32: Área IV | D32: Vedam expressamente trabalho escravo ou em condições análogas? | G32: DIM_PACTO do modelo Simples GRC; redação sintética a validar no SAMPI
A33: PB-035 | B33: 7.2 | C33: Área IV | D33: As políticas e procedimentos foram aplicados periodicamente nos últimos 12 meses? | E33: QPE-083 | F33: 9.3 | G33: DIM_PACTO do modelo Simples GRC; redação sintética a validar no SAMPI
A34: PB-037 | B34: 8.2 | C34: Área V | D34: Os treinamentos são planejados considerando características de cada público-alvo? | E34: QPE-103 | F34: 11.1.4 | G34: DIM_PACTO do modelo Simples GRC; redação sintética a validar no SAMPI
A35: PB-038 | B35: 8.3 | C35: Área V | D35: Os treinamentos atingiram percentual relevante do público-alvo? | E35: QPE-114 | F35: 11.4.2 | G35: DIM_PACTO do modelo Simples GRC; redação sintética a validar no SAMPI
A36: PB-040 | B36: 9.2.1 | C36: Área V | D36: As ações difundiram aspectos gerais do programa como Código e Canal de Denúncia? | E36: QPE-122; QPE-123 | F36: 12.3.1; 12.3.2 | G36: DIM_PACTO do modelo Simples GRC; redação sintética a validar no SAMPI
A37: PB-041 | B37: 9.2.2 | C37: Área V | D37: Buscaram difundir necessidade de prevenir assédio e discriminação? | E37: QPE-124 | F37: 12.3.3 | G37: DIM_PACTO do modelo Simples GRC; redação sintética a validar no SAMPI
A38: PB-042 | B38: 9.2.3 | C38: Área V | D38: Buscaram difundir importância da preservação ambiental e desenvolvimento sustentável? | E38: QPE-125 | F38: 12.3.4 | G38: DIM_PACTO do modelo Simples GRC; redação sintética a validar no SAMPI
A39: PB-043 | B39: 10.1 | C39: Área VI | D39: Possui procedimentos definidos para lançamentos contábeis com fluxogramas e segregação? | E39: QPE-132; QPE-133; QPE-134 | F39: 14.1; 14.2; 14.3 | G39: DIM_PACTO do modelo Simples GRC; redação sintética a validar no SAMPI
A40: PB-044 | B40: 10.2 | C40: Área VI | D40: Os registros contábeis são feitos de forma detalhada para evitar irregularidades? | E40: QPE-135 | F40: 14.4 | G40: DIM_PACTO do modelo Simples GRC; redação sintética a validar no SAMPI
A41: PB-045 | B41: 10.3 | C41: Área VI | D41: Possui área de auditoria interna, formalizada ou terceirizada? | E41: QPE-137 | F41: 15.1 | G41: DIM_PACTO do modelo Simples GRC; redação sintética a validar no SAMPI
A42: PB-046 | B42: 11.1.1 | C42: Área VII | D42: Realiza diligências verificando possível envolvimento em corrupção e fraude? | E42: QPE-144 | F42: 16.1.2 | G42: DIM_PACTO do modelo Simples GRC; redação sintética a validar no SAMPI
A43: PB-047 | B43: 11.1.2 | C43: Área VII | D43: Verifica registro em listas sujas de trabalho escravo? | G43: DIM_PACTO do modelo Simples GRC; redação sintética a validar no SAMPI
...

Sheet II_PACTO_QPE_76
A1: Etapa II · Perguntas QPE correlatas ao Pacto Brasil (76)
A2: Fonte: portal (DB.Q trilha Pacto Brasil). Com as 10 Essenciais e as 137 do Pró-Ética completam as 223 QPE.
A4: ID | B4: Nº formulário | C4: Trilha | D4: Área | E4: Pergunta | F4: Evidência sugerida | G4: Peso (pts) | H4: Agente | I4: Tipo de verificação | J4: Natureza | K4: Janela | L4: Itens do Pacto | M4: Itens ISO | N4: Incisos art. 57 | O4: Licitações? | P4: Medida essencial (ITP)
A5: QPE-075 | B5: 9.1.3 | C5: Pacto Brasil | D5: Código de Ética, Políticas e Procedimentos | E5: A empresa possui políticas e procedimentos de integridade que: tratam da prevenção de conflito de interesses nas relações com a Administração Pública, incluindo contratações de agentes públicos, pessoas expostas politicamente, seus familiares, estreitos colaboradores e pessoas jurídicas de que participem? | F5: tratam da prevenção de conflitos de interesse nas relações com a Administração Pública, incluindo contratações de agentes públicos, suas famílias, colaboradores e pessoas jurídicas relacionadas;; POL-02 — Conflito de Interesses | POL-05 — Relacionamento com o Setor Público | G5: 0.3 | H5: AG-FCG-QPE-075 | I5: GOVERNANCA | J5: Desenho | K5: VIGENTE | L5: 7.1.3 | M5: ISO-16; ISO-23; ISO-31 | N5: VIII | O5: Sim
A6: QPE-001 | B6: 1.1 | C6: Pacto Brasil | D6: Comprometimento da Alta Direção | E6: A empresa possui critérios de integridade formalizados para seleção dos candidatos aos cargos da alta direção, inclusive para escolha de membros da alta direção de suas controladas/subsidiárias, quando for o caso? Se sim, informar os cargos a que são aplicados, a forma como são considerados no processo de seleção e os responsáveis por sua avaliação. | F6: Documentos que comprovem que a empresa possui critérios formalizados relacionados à integridade para escolha de membros da alta direção, tais como política de seleção, procedimentos de contratação. | G6: 1 | H6: AG-FCG-QPE-001 | I6: GOVERNANCA | J6: Desenho | K6: VIGENTE | L6: 3.1 | M6: ISO-22; ISO-23 | N6: I
A7: QPE-002 | B7: 1.2 | C7: Pacto Brasil | D7: Comprometimento da Alta Direção | E7: A empresa aplica critérios de integridade para seleção dos candidatos aos cargos da alta direção, inclusive para escolha de membros da alta direção de suas controladas/subsidiárias, quando for o caso? Se sim, informar se foram aplicados no processo de seleção dos atuais membros da alta direção e dos membros da alta direção de controladas/subsidiárias da empresa, quando for o caso. | F7: Documentos que comprovem que a empresa aplica critérios de integridade para escolha de membros da alta direção, tais como: testes de integridade, background check, know your employee – KYE, realização de pesquisas em fontes abertas, e outros critérios análogos que demonstrem avaliação do histórico profissional, casos de envolvimento em práticas de corrupção, fraude e outros ilícitos, bem como outras análises de antecedentes que impactem numa conduta íntegra. | G7: 1.2 | H7: AG-FCG-QPE-002 | I7: GOVERNANCA | J7: Execução | K7: PERIODO | L7: 3.1 | M7: ISO-22; ISO-23 | N7: I
A8: QPE-004 | B8: 1.4 | C8: Pacto Brasil | D8: Comprometimento da Alta Direção | E8: A política de remuneração variável para os membros da alta direção está condicionada ao atingimento de metas de desempenho relacionadas aos indicadores de aplicação do programa de integridade? | F8: Política, norma ou procedimento formal, aprovado pela direção da empresa, que disponha sobre regras que condicionem a remuneração variável dos membros da alta direção ao atingimento de metas relacionadas aos indicadores de aplicação do programa de integridade.; Documento normativo do tema explicitamente citado na pergunta; não atribuir automaticamente uma das 11 políticas essenciais. | G8: 0.1 | H8: AG-FCG-QPE-004 | I8: GOVERNANCA | J8: Desenho | K8: VIGENTE | L8: 3.2 | M8: ISO-10; ISO-25 | N8: I
A9: QPE-005 | B9: 2.1 | C9: Pacto Brasil | D9: Comprometimento da Alta Direção | E9: A aprovação das principais políticas relacionadas ao programa de integridade é feita pelas mais elevadas instâncias decisórias da empresa? | F9: Documentos que indiquem a forma como a alta direção participou da aprovação das principais políticas relacionadas ao programa de integridade, tais como: − atas de reuniões, e-mails ou outros documentos que comprovem que houve aprovação de criação ou atualização de estruturas, políticas ou procedimentos do programa de integridade pelos membros da alta direção; e registros incluídos na própria política. | G9: 0.9 | H9: AG-FCG-QPE-005 | I9: GOVERNANCA | J9: Execução | K9: PERIODO | L9: 2.1 | M9: ISO-08; ISO-12; ISO-48 | N9: I
A10: QPE-013 | B10: 2.5 | C10: Pacto Brasil | D10: Comprometimento da Alta Direção | E10: A alta direção da empresa incentiva o debate, a aprovação e a aplicação efetiva de normas, políticas e procedimentos relacionados com a preservação do meio ambiente, a redução ou eliminação da sua parcela de contribuição aos efeitos das mudanças climáticas e o combate à corrupção ambiental? | F10: Atas de reunião, comunicações internas, manifestações pessoais ou outros documentos que comprovem o incentivo da alta direção ao debate, aprovação e a aplicação efetiva de normas, políticas e procedimentos relacionados aos temas mencionados. | G10: 0.1 | H10: AG-FCG-QPE-013 | I10: PUBLICACAO_COMUNICACAO | J10: Execução | K10: PERIODO | L10: 1.4 | M10: ISO-09 | N10: I
A11: QPE-014 | B11: 3.1 | C11: Pacto Brasil | D11: Comprometimento da Alta Direção | E11: Os membros da alta direção, de forma pessoalizada, manifestam publicamente apoio ao programa de integridade? | F11: Mensagens ostensivas e identificáveis dos membros da alta direção aos funcionários da empresa, à sociedade, ao mercado, aos fornecedores e demais stakeholders, promovendo o comportamento ético e demonstrando o compromisso da empresa com a prevenção e o combate à corrupção (p.ex.: e-mails, redes sociais, intranet, vídeos institucionais e comunicados internos e externos), nos quais constem de forma visível e inequívoca, apoio ao programa de integridade e à importância da defesa da ética e integridade nas relações negociais, principalmente nas relações com o setor público. | G11: 0.4 | H11: AG-FCG-QPE-014 | I11: GOVERNANCA | J11: Execução | K11: PERIODO | L11: 1.2 | M11: ISO-09; ISO-10 | N11: I
A12: QPE-019 | B12: 3.2.5 | C12: Pacto Brasil | D12: Comprometimento da Alta Direção | E12: As manifestações de apoio ao programa de integridade: expressam uma mensagem de incentivo à adoção de uma conduta ética, seguindo os ditames do programa de integridade? (questão direcionada ao avaliador) | F12: Evidências de mensagens claras da alta direção aos colaboradores, sociedade, mercado e stakeholders, reforçando o compromisso da empresa no combate ao preconceito, à discriminação e ao assédio em qualquer forma. | G12: 0.3 | H12: AG-FCG-QPE-019 | I12: GOVERNANCA | J12: Avaliador | L12: 1.3 | M12: ISO-09; ISO-10 | N12: I
A13: QPE-020 | B13: 3.2.6 | C13: Pacto Brasil | D13: Comprometimento da Alta Direção | E13: As manifestações de apoio ao programa de integridade: expressam o compromisso da alta direção com o combate ao preconceito, à discriminação e ao assédio de qualquer natureza? | F13: Evidências de mensagens claras da alta direção aos colaboradores, sociedade, mercado e stakeholders, reforçando o compromisso da empresa no combate ao preconceito, à discriminação e ao assédio em qualquer forma. | G13: 0.1 | H13: AG-FCG-QPE-020 | I13: GOVERNANCA | J13: Execução | K13: PERIODO | L13: 1.4 | M13: ISO-09; ISO-10 | N13: I
A14: QPE-025 | B14: 4.2.1 | C14: Pacto Brasil | D14: Instância Responsável pelo Programa | E14: A instância interna responsável pelo programa de integridade: *está formalmente constituída, tendo suas atribuições expressamente previstas em documento aprovado pela alta direção da empresa? (*Medida mínima prevista no art. 14 do Regulamento, de caráter obrigatório) | F14: Regimento, estatuto, manuais, políticas, procedimentos ou outros documentos que estabeleçam a forma de organização do setor, incluindo a indicação da quantidade de funcionários dedicados exclusivamente ao programa de integridade e a respectiva qualificação; Descritivo dos principais cargos da área de integridade, incluindo-se o do chefe da área; Ata de reunião de assembleia geral de acionistas ou deliberação constante de ata de reunião de conselho de administração ou diretoria em que haja deliberação sobre a criação, as atribuições e o funcionamento do setor; “4.2”. Atentar que a data de criação da área ou designação do responsável deve ser até 30/04/2024. Obs.: A data de aprovação deve estar indicada no próprio documento ou, quando inexistente, deve ser enviado cópia do ato de sua aprovação em que conste a referida data. | G14: 1.4 | H14: AG-FCG-QPE-025 | I14: GOVERNANCA | J14: Desenho | K14: VIGENTE | L14: 4.2 | M14: ISO-13; ISO-14 | N14: IX
A15: QPE-037 | B15: 6.1 | C15: Pacto Brasil | D15: Gestão de Riscos para a Integridade | E15: Existe na empresa política ou planejamento que trate da gestão de riscos e que defina a metodologia para a realização da análise de riscos? | F15: Documento normativo do tema explicitamente citado na pergunta; não atribuir automaticamente uma das 11 políticas essenciais. | G15: 0.2 | H15: AG-FCG-QPE-037 | I15: RISCOS_TERCEIROS | J15: Desenho | K15: VIGENTE | L15: 5.4 | M15: ISO-07 | N15: V
A16: QPE-038 | B16: 6.1.1 | C16: Pacto Brasil | D16: Gestão de Riscos para a Integridade | E16: A política ou planejamento que trata da gestão de riscos institui a periodicidade mínima para atualização/revisão do processo de análise de riscos? | F16: periodicidade mínima para atualização/revisão do processo de gestão de riscos;; Documento normativo do tema explicitamente citado na pergunta; não atribuir automaticamente uma das 11 políticas essenciais. | G16: 0.5 | H16: AG-FCG-QPE-038 | I16: RISCOS_TERCEIROS | J16: Desenho | K16: VIGENTE | L16: 5.4 | M16: ISO-07 | N16: V
A17: QPE-042 | B17: 6.3.1 | C17: Pacto Brasil | D17: Gestão de Riscos para a Integridade | E17: A análise de riscos para a integridade realizada contempla: a classificação dos riscos com base em sua probabilidade e impacto? | F17: Política ou planejamento da empresa, aprovado(s) pela alta direção, que trate da gestão de riscos e que defina a metodologia de análise de riscos, contendo: a descrição dos riscos de integridade, avaliando sua probabilidade e impacto; | G17: 0.7 | H17: AG-FCG-QPE-042 | I17: RISCOS_TERCEIROS | J17: Execução | K17: PERIODO | L17: 5.2 | M17: ISO-07 | N17: V
A18: QPE-043 | B18: 6.3.2 | C18: Pacto Brasil | D18: Gestão de Riscos para a Integridade | E18: A análise de riscos para a integridade realizada contempla: O tratamento indicado para cada um dos riscos identificados? | F18: Política ou planejamento da empresa, aprovado(s) pela alta direção, que trate da gestão de riscos e que defina a metodologia de análise de riscos, contendo: a identificação, classificação e indicando o tratamento para cada risco de integridade; | G18: 1.5 | H18: AG-FCG-QPE-043 | I18: RISCOS_TERCEIROS | J18: Execução | K18: PERIODO | L18: 5.3 | M18: ISO-07; ISO-17 | N18: V
A19: QPE-044 | B19: 6.3.3 | C19: Pacto Brasil | D19: Gestão de Riscos para a Integridade | E19: A análise de riscos para a integridade realizada contempla: Os responsáveis pelo tratamento dos riscos identificados? | F19: Política ou planejamento da empresa, aprovado(s) pela alta direção, que trate da gestão de riscos e que defina a metodologia de análise de riscos, contendo: a identificação dos responsáveis pelo tratamento dos riscos apontados; | G19: 1 | H19: AG-FCG-QPE-044 | I19: RISCOS_TERCEIROS | J19: Execução | K19: PERIODO | L19: 5.3 | M19: ISO-07; ISO-13; ISO-17 | N19: V
